<?xml version="1.0" encoding="utf-8"?>
<!-- This URDF was automatically created by SolidWorks to URDF Exporter! Originally created by Stephen Brawner (brawner@gmail.com) 
     Commit Version: 1.6.0-1-g15f4949  Build Version: 1.6.7594.29634
     For more information, please see http://wiki.ros.org/sw_urdf_exporter -->
<robot name="with_head_urdf">
  <link name="base_link">
    <inertial>
      <origin xyz="0.013297568333136 0.00019471059807924 0.23238884588487" rpy="0 0 0" />
      <mass value="5.40076291054089" />
      <inertia ixx="0.187153854017537" ixy="0.000183137763645028" ixz="-0.00103405104744054" iyy="0.150146401982878" iyz="-1.05977543431583E-05" izz="0.130778576984984" />
    </inertial>
    <visual>
      <origin xyz="0 0 0" rpy="0 0 0" />
      <geometry>
        <mesh filename="package://mh2_description/meshes/base_link.STL" />
      </geometry>
      <material name="">
        <color rgba="1 1 1 1" />
      </material>
    </visual>
    <collision>
      <origin xyz="0 0 0" rpy="0 0 0" />
      <geometry>
        <mesh filename="package://mh2_description/meshes/base_link.STL" />
      </geometry>
    </collision>
  </link>
  <link name="left_wheel">
    <inertial>
      <origin xyz="-1.71410420329865E-07 4.41481490896234E-05 8.87974609398157E-07" rpy="0 0 0" />
      <mass value="0.340038404429615" />
      <inertia ixx="0.000561221491910563" ixy="-1.01822234052541E-08" ixz="4.53425603205083E-09" iyy="0.000985894422796474" iyz="-3.15034765179964E-09" izz="0.000561255208762851" />
    </inertial>
    <visual>
      <origin xyz="0 0 0" rpy="0 0 0" />
      <geometry>
        <mesh filename="package://mh2_description/meshes/left_wheel.STL" />
      </geometry>
      <material name="">
        <color rgba="1 1 1 1" />
      </material>
    </visual>
    <collision>
      <origin xyz="0 0 0" rpy="0 0 0" />
      <geometry>
        <mesh filename="package://mh2_description/meshes/left_wheel.STL" />
      </geometry>
    </collision>
  </link>
  <joint name="left_wheel_joint" type="continuous">
    <origin xyz="0.011193 0.1968 0.038" rpy="0 0 -2.566E-05" />
    <parent link="base_link" />
    <child link="left_wheel" />
    <axis xyz="0 1 0" />
  </joint>
  <link name="right_wheel">
    <inertial>
      <origin xyz="1.71410420454765E-07 -4.41481490896511E-05 8.87974609842246E-07" rpy="0 0 0" />
      <mass value="0.340038404429611" />
      <inertia ixx="0.000561221491910557" ixy="-1.01822234051344E-08" ixz="-4.53425603010855E-09" iyy="0.000985894422796462" iyz="3.15034763504468E-09" izz="0.000561255208762845" />
    </inertial>
    <visual>
      <origin xyz="0 0 0" rpy="0 0 0" />
      <geometry>
        <mesh filename="package://mh2_description/meshes/right_wheel.STL" />
      </geometry>
      <material name="">
        <color rgba="1 1 1 1" />
      </material>
    </visual>
    <collision>
      <origin xyz="0 0 0" rpy="0 0 0" />
      <geometry>
        <mesh filename="package://mh2_description/meshes/right_wheel.STL" />
      </geometry>
    </collision>
  </link>
  <joint name="right_wheel_joint" type="continuous">
    <origin xyz="0.011193 -0.19675 0.038" rpy="0 0 -2.566E-05" />
    <parent link="base_link" />
    <child link="right_wheel" />
    <axis xyz="0 1 0" />
  </joint>
  <link name="body_link">
    <inertial>
      <origin xyz="-0.0803040419263677 3.33582781098796E-05 -0.133793556482102" rpy="0 0 0" />
      <mass value="1.78690027101954" />
      <inertia ixx="0.0436122698944514" ixy="2.25749334819619E-08" ixz="-0.000359370506472603" iyy="0.0350117659677819" iyz="-4.02808207850723E-06" izz="0.0144191315071659" />
    </inertial>
    <visual>
      <origin xyz="0 0 0" rpy="0 0 0" />
      <geometry>
        <mesh filename="package://mh2_description/meshes/body_link.STL" />
      </geometry>
      <material name="">
        <color rgba="1 1 1 1" />
      </material>
    </visual>
    <collision>
      <origin xyz="0 0 0" rpy="0 0 0" />
      <geometry>
        <mesh filename="package://mh2_description/meshes/body_link.STL" />
      </geometry>
    </collision>
  </link>
  <joint name="body_joint" type="prismatic">
    <origin xyz="0.011194 0 0.953" rpy="0 0 -1.283E-05" />
    <parent link="base_link" />
    <child link="body_link" />
    <axis xyz="0 0 1" />
    <limit lower="0" upper="0" effort="0" velocity="0" />
  </joint>
  <link name="link_la0">
    <inertial>
      <origin xyz="-4.39082619964337E-06 0.0351511040612831 0.00290057160722212" rpy="0 0 0" />
      <mass value="0.136094659507165" />
      <inertia ixx="0.000346146513078443" ixy="4.37028746590146E-08" ixz="-9.40840014047286E-10" iyy="0.000204217936134438" iyz="1.37715760377022E-05" izz="0.000342416278108824" />
    </inertial>
    <visual>
      <origin xyz="0 0 0" rpy="0 0 0" />
      <geometry>
        <mesh filename="package://mh2_description/meshes/link_la0.STL" />
      </geometry>
      <material name="">
        <color rgba="1 1 1 1" />
      </material>
    </visual>
    <collision>
      <origin xyz="0 0 0" rpy="0 0 0" />
      <geometry>
        <mesh filename="package://mh2_description/meshes/link_la0.STL" />
      </geometry>
    </collision>
  </link>
  <joint name="joint_la0" type="revolute">
    <origin xyz="0 0.0595 0" rpy="0 0 0" />
    <parent link="body_link" />
    <child link="link_la0" />
    <axis xyz="0 0 1" />
    <limit lower="-1.046" upper="1.0416" effort="0" velocity="0" />
  </joint>
  <link name="link_la1">
    <inertial>
      <origin xyz="-0.013036755293977 0.0585029037551869 0.000536491760941615" rpy="0 0 0" />
      <mass value="0.0889255858183926" />
      <inertia ixx="0.000152307732827254" ixy="2.91370812639673E-05" ixz="-2.23718366126422E-06" iyy="0.00010860562176724" iyz="3.27376412138607E-07" izz="0.000143809674512415" />
    </inertial>
    <visual>
      <origin xyz="0 0 0" rpy="0 0 0" />
      <geometry>
        <mesh filename="package://mh2_description/meshes/link_la1.STL" />
      </geometry>
      <material name="">
        <color rgba="1 1 1 1" />
      </material>
    </visual>
    <collision>
      <origin xyz="0 0 0" rpy="0 0 0" />
      <geometry>
        <mesh filename="package://mh2_description/meshes/link_la1.STL" />
      </geometry>
    </collision>
  </link>
  <joint name="joint_la1" type="revolute">
    <origin xyz="0 0.122 0" rpy="0 0 0" />
    <parent link="link_la0" />
    <child link="link_la1" />
    <axis xyz="0 1 0" />
    <limit lower="-1.74" upper="0.785" effort="0" velocity="0" />
  </joint>
  <link name="link_la2">
    <inertial>
      <origin xyz="-0.0242964206056061 -0.00366330359038974 -0.0877394711478853" rpy="0 0 0" />
      <mass value="0.0738333124310636" />
      <inertia ixx="0.000162818669511176" ixy="-6.99289310314609E-07" ixz="-6.17447212214061E-06" iyy="9.81053886493855E-05" iyz="4.90886279395145E-06" izz="0.000102693003324456" />
    </inertial>
    <visual>
      <origin xyz="0 0 0" rpy="0 0 0" />
      <geometry>
        <mesh filename="package://mh2_description/meshes/link_la2.STL" />
      </geometry>
      <material name="">
        <color rgba="1 1 1 1" />
      </material>
    </visual>
    <collision>
      <origin xyz="0 0 0" rpy="0 0 0" />
      <geometry>
        <mesh filename="package://mh2_description/meshes/link_la2.STL" />
      </geometry>
    </collision>
  </link>
  <joint name="joint_la2" type="revolute">
    <origin xyz="0 0.0905 0" rpy="0 0 0" />
    <parent link="link_la1" />
    <child link="link_la2" />
    <axis xyz="1 0 0" />
    <limit lower="0" upper="1.57" effort="0" velocity="0" />
  </joint>
  <link name="link_la3">
    <inertial>
      <origin xyz="-0.0012464 0.01242 -0.082454" rpy="0 0 0" />
      <mass value="0.13678" />
      <inertia ixx="0.00038008" ixy="-7.014E-06" ixz="-5.0989E-06" iyy="0.00040369" iyz="4.686E-05" izz="0.00023809" />
    </inertial>
    <visual>
      <origin xyz="0 0 0" rpy="0 0 0" />
      <geometry>
        <mesh filename="package://mh2_description/meshes/link_la3.STL" />
      </geometry>
      <material name="">
        <color rgba="1 1 1 1" />
      </material>
    </visual>
    <collision>
      <origin xyz="0 0 0" rpy="0 0 0" />
      <geometry>
        <mesh filename="package://mh2_description/meshes/link_la3.STL" />
      </geometry>
    </collision>
  </link>
  <joint name="joint_la3" type="revolute">
    <origin xyz="0 0 -0.13647" rpy="0 0 0" />
    <parent link="link_la2" />
    <child link="link_la3" />
    <axis xyz="0 0 1" />
    <limit lower="-2.79" upper="2.79" effort="0" velocity="0" />
  </joint>
  <link name="link_la4">
    <inertial>
      <origin xyz="-0.0016995 -0.010291 -0.053884" rpy="0 0 0" />
      <mass value="0.12227" />
      <inertia ixx="0.00033025" ixy="7.3521E-06" ixz="3.3076E-06" iyy="0.00033326" iyz="5.4661E-05" izz="0.00014824" />
    </inertial>
    <visual>
      <origin xyz="0 0 0" rpy="0 0 0" />
      <geometry>
        <mesh filename="package://mh2_description/meshes/link_la4.STL" />
      </geometry>
      <material name="">
        <color rgba="1 1 1 1" />
      </material>
    </visual>
    <collision>
      <origin xyz="0 0 0" rpy="0 0 0" />
      <geometry>
        <mesh filename="package://mh2_description/meshes/link_la4.STL" />
      </geometry>
    </collision>
  </link>
  <joint name="joint_la4" type="revolute">
    <origin xyz="0 0 -0.13753" rpy="0 0 0" />
    <parent link="link_la3" />
    <child link="link_la4" />
    <axis xyz="0 1 0" />
    <limit lower="-2.23" upper="0" effort="0" velocity="0" />
  </joint>
  <link name="link_la5">
    <inertial>
      <origin xyz="0.00746173001672608 1.98792844113838E-06 -0.0598979228162384" rpy="0 0 0" />
      <mass value="0.0949534366161622" />
      <inertia ixx="0.000157481269955815" ixy="4.33779216873321E-09" ixz="1.8953257503321E-05" iyy="0.000159540644764976" iyz="-4.08015831830362E-08" izz="0.00010312341644402" />
    </inertial>
    <visual>
      <origin xyz="0 0 0" rpy="0 0 0" />
      <geometry>
        <mesh filename="package://mh2_description/meshes/link_la5.STL" />
      </geometry>
      <material name="">
        <color rgba="1 1 1 1" />
      </material>
    </visual>
    <collision>
      <origin xyz="0 0 0" rpy="0 0 0" />
      <geometry>
        <mesh filename="package://mh2_description/meshes/link_la5.STL" />
      </geometry>
    </collision>
  </link>
  <joint name="joint_la5" type="revolute">
    <origin xyz="0 0 -0.14175" rpy="0 0 0" />
    <parent link="link_la4" />
    <child link="link_la5" />
    <axis xyz="0 0 1" />
    <limit lower="-2.79" upper="2.79" effort="0" velocity="0" />
  </joint>
  <link name="link_la6">
    <inertial>
      <origin xyz="0.0010862513515508 0.00393104540374184 -0.00051793625628993" rpy="0 0 0" />
      <mass value="0.0248001443279318" />
      <inertia ixx="1.52733707658762E-05" ixy="1.5467450087201E-07" ixz="-1.36967445335629E-08" iyy="1.78030572119572E-05" iyz="-7.72651255383898E-08" izz="1.61772455912256E-05" />
    </inertial>
    <visual>
      <origin xyz="0 0 0" rpy="0 0 0" />
      <geometry>
        <mesh filename="package://mh2_description/meshes/link_la6.STL" />
      </geometry>
      <material name="">
        <color rgba="1 1 1 1" />
      </material>
    </visual>
    <collision>
      <origin xyz="0 0 0" rpy="0 0 0" />
      <geometry>
        <mesh filename="package://mh2_description/meshes/link_la6.STL" />
      </geometry>
    </collision>
  </link>
  <joint name="joint_la6" type="revolute">
    <origin xyz="-0.007347 0 -0.13425" rpy="0 0 0" />
    <parent link="link_la5" />
    <child link="link_la6" />
    <axis xyz="1 0 0" />
    <limit lower="-0.69" upper="0.69" effort="0" velocity="0" />
  </joint>
  <link name="link_la7">
    <inertial>
      <origin xyz="-1.70760540378623E-06 0.023377253263407 -0.0285388615872149" rpy="0 0 0" />
      <mass value="0.0325008367413874" />
      <inertia ixx="2.74872742802843E-05" ixy="1.55303602337843E-10" ixz="3.9887174471211E-10" iyy="2.41263324697153E-05" iyz="-7.53556723666935E-06" izz="2.05780265839898E-05" />
    </inertial>
    <visual>
      <origin xyz="0 0 0" rpy="0 0 0" />
      <geometry>
        <mesh filename="package://mh2_description/meshes/link_la7.STL" />
      </geometry>
      <material name="">
        <color rgba="1 1 1 1" />
      </material>
    </visual>
    <collision>
      <origin xyz="0 0 0" rpy="0 0 0" />
      <geometry>
        <mesh filename="package://mh2_description/meshes/link_la7.STL" />
      </geometry>
    </collision>
  </link>
  <joint name="joint_la7" type="revolute">
    <origin xyz="0 0 0" rpy="0 0 0" />
    <parent link="link_la6" />
    <child link="link_la7" />
    <axis xyz="0 1 0" />
    <limit lower="-0.69" upper="0.69" effort="0" velocity="0" />
  </joint>
  <link name="link_tcp_l" />
  <joint name="joint_tcp_l" type="fixed">
    <origin xyz="0 0 0" rpy="0 0 0" />
    <parent link="link_la7" />
    <child link="link_tcp_l" />
    <axis xyz="0 0 0" />
  </joint>


  <link name="link_lf0">
    <inertial>
      <origin xyz="-0.0034457 -0.003067 -0.04984" rpy="0 0 0" />
      <mass value="0.029012" />
      <inertia ixx="3.2264E-06" ixy="1.7292E-08" ixz="-8.6928E-09" iyy="4.5079E-06" iyz="3.4255E-07" izz="2.1813E-06" />
    </inertial>
    <visual>
      <origin xyz="0 0 0" rpy="0 0 0" />
      <geometry>
        <mesh filename="package://mh2_description/meshes/link_lf0.STL" />
      </geometry>
      <material name="">
        <color rgba="1 1 1 1" />
      </material>
    </visual>
    <collision>
      <origin xyz="0 0 0" rpy="0 0 0" />
      <geometry>
        <mesh filename="package://mh2_description/meshes/link_lf0.STL" />
      </geometry>
    </collision>
  </link>
  <joint name="joint_lf0" type="revolute">
    <origin xyz="0 -0.0107 -0.10394" rpy="0 0.032918 0" />
    <parent link="link_la7" />
    <child link="link_lf0" />
    <axis xyz="1 0 0" />
    <limit lower="0" upper="0" effort="0" velocity="0" />
  </joint>
  <link name="link_lf1">
    <inertial>
      <origin xyz="-0.0033855 0.0030662 -0.04984" rpy="0 0 0" />
      <mass value="0.029012" />
      <inertia ixx="3.2264E-06" ixy="1.8928E-08" ixz="1.4265E-08" iyy="4.5076E-06" iyz="-3.4297E-07" izz="2.1815E-06" />
    </inertial>
    <visual>
      <origin xyz="0 0 0" rpy="0 0 0" />
      <geometry>
        <mesh filename="package://mh2_description/meshes/link_lf1.STL" />
      </geometry>
      <material name="">
        <color rgba="1 1 1 1" />
      </material>
    </visual>
    <collision>
      <origin xyz="0 0 0" rpy="0 0 0" />
      <geometry>
        <mesh filename="package://mh2_description/meshes/link_lf1.STL" />
      </geometry>
    </collision>
  </link>
  <joint name="joint_lf1" type="revolute">
    <origin xyz="0 0.0123 -0.10394" rpy="0 0.032918 0" />
    <parent link="link_la7" />
    <child link="link_lf1" />
    <axis xyz="1 0 0" />
    <limit lower="0" upper="0" effort="0" velocity="0" />
  </joint>






  <link name="link_ra0">
    <inertial>
      <origin xyz="4.39082600889318E-06 -0.0351511040601273 0.00290057160749013" rpy="0 0 0" />
      <mass value="0.136094659505576" />
      <inertia ixx="0.000346146513052836" ixy="4.37028719281858E-08" ixz="9.40839380733047E-10" iyy="0.000204217936133089" iyz="-1.37715760338982E-05" izz="0.00034241627808366" />
    </inertial>
    <visual>
      <origin xyz="0 0 0" rpy="0 0 0" />
      <geometry>
        <mesh filename="package://mh2_description/meshes/link_ra0.STL" />
      </geometry>
      <material name="">
        <color rgba="1 1 1 1" />
      </material>
    </visual>
    <collision>
      <origin xyz="0 0 0" rpy="0 0 0" />
      <geometry>
        <mesh filename="package://mh2_description/meshes/link_ra0.STL" />
      </geometry>
    </collision>
  </link>
  <joint name="joint_ra0" type="revolute">
    <origin xyz="0 -0.0595 0" rpy="0 0 0" />
    <parent link="body_link" />
    <child link="link_ra0" />
    <axis xyz="0 0 1" />
    <limit lower="-1.046" upper="1.046" effort="0" velocity="0" />
  </joint>
  <link name="link_ra1">
    <inertial>
      <origin xyz="-0.00815251717011797 0.185536550484873 -0.744459856136913" rpy="0 0 0" />
      <mass value="14.5391646162314" />
      <inertia ixx="3.66135816778634" ixy="-0.00371648187645327" ixz="0.0428882559260392" iyy="3.57156287219214" iyz="-0.0389296681786129" izz="0.455888006729818" />
    </inertial>
    <visual>
      <origin xyz="0 0 0" rpy="0 0 0" />
      <geometry>
        <mesh filename="package://mh2_description/meshes/link_ra1.STL" />
      </geometry>
      <material name="">
        <color rgba="1 1 1 1" />
      </material>
    </visual>
    <collision>
      <origin xyz="0 0 0" rpy="0 0 0" />
      <geometry>
        <mesh filename="package://mh2_description/meshes/link_ra1.STL" />
      </geometry>
    </collision>
  </link>
  <joint name="joint_ra1" type="revolute">
    <origin xyz="0 -0.122 0" rpy="0 0 0" />
    <parent link="link_ra0" />
    <child link="link_ra1" />
    <axis xyz="0 1 0" />
    <limit lower="-1.74" upper="0.785" effort="0" velocity="0" />
  </joint>
  <link name="link_ra2">
    <inertial>
      <origin xyz="-0.021285122827746 0.00339128841639386 -0.0908433171127738" rpy="0 0 0" />
      <mass value="0.0792244377670603" />
      <inertia ixx="0.000163207633984652" ixy="7.24950712317726E-07" ixz="-6.16596450280992E-06" iyy="9.82854680982752E-05" iyz="-5.00147411634078E-06" izz="0.000103125297891135" />
    </inertial>
    <visual>
      <origin xyz="0 0 0" rpy="0 0 0" />
      <geometry>
        <mesh filename="package://mh2_description/meshes/link_ra2.STL" />
      </geometry>
      <material name="">
        <color rgba="1 1 1 1" />
      </material>
    </visual>
    <collision>
      <origin xyz="0 0 0" rpy="0 0 0" />
      <geometry>
        <mesh filename="package://mh2_description/meshes/link_ra2.STL" />
      </geometry>
    </collision>
  </link>
  <joint name="joint_ra2" type="revolute">
    <origin xyz="0 -0.0905 0" rpy="0 0 0" />
    <parent link="link_ra1" />
    <child link="link_ra2" />
    <axis xyz="1 0 0" />
    <limit lower="-1.57" upper="0" effort="0" velocity="0" />
  </joint>
  <link name="link_ra3">
    <inertial>
      <origin xyz="-0.0081535 0.27604 -0.60799" rpy="0 0 0" />
      <mass value="14.539" />
      <inertia ixx="3.6614" ixy="-0.0037165" ixz="0.042888" iyy="3.5716" iyz="-0.03893" izz="0.45589" />
    </inertial>
    <visual>
      <origin xyz="0 0 0" rpy="0 0 0" />
      <geometry>
        <mesh filename="package://mh2_description/meshes/link_ra3.STL" />
      </geometry>
      <material name="">
        <color rgba="1 1 1 1" />
      </material>
    </visual>
    <collision>
      <origin xyz="0 0 0" rpy="0 0 0" />
      <geometry>
        <mesh filename="package://mh2_description/meshes/link_ra3.STL" />
      </geometry>
    </collision>
  </link>
  <joint name="joint_ra3" type="revolute">
    <origin xyz="0 0 -0.13647" rpy="0 0 0" />
    <parent link="link_ra2" />
    <child link="link_ra3" />
    <axis xyz="0 0 1" />
    <limit lower="-2.79" upper="2.79" effort="0" velocity="0" />
  </joint>
  <link name="link_ra4">
    <inertial>
      <origin xyz="-0.00169875365366506 0.0102900881795698 -0.0538819602737075" rpy="0 0 0" />
      <mass value="0.122252670721065" />
      <inertia ixx="0.000330250152032449" ixy="-7.34588255188123E-06" ixz="3.26383760634614E-06" iyy="0.000333254561428555" iyz="-5.46653967528714E-05" izz="0.000148235091591316" />
    </inertial>
    <visual>
      <origin xyz="0 0 0" rpy="0 0 0" />
      <geometry>
        <mesh filename="package://mh2_description/meshes/link_ra4.STL" />
      </geometry>
      <material name="">
        <color rgba="1 1 1 1" />
      </material>
    </visual>
    <collision>
      <origin xyz="0 0 0" rpy="0 0 0" />
      <geometry>
        <mesh filename="package://mh2_description/meshes/link_ra4.STL" />
      </geometry>
    </collision>
  </link>
  <joint name="joint_ra4" type="revolute">
    <origin xyz="0 0 -0.13753" rpy="0 0 0" />
    <parent link="link_ra3" />
    <child link="link_ra4" />
    <axis xyz="0 1 0" />
    <limit lower="-2.23" upper="0" effort="0" velocity="0" />
  </joint>
  <link name="link_ra5">
    <inertial>
      <origin xyz="0.00746142723654677 1.98798606887429E-06 -0.0598979665709705" rpy="0 0 0" />
      <mass value="0.0949534442060658" />
      <inertia ixx="0.000157481507882346" ixy="4.33780642784271E-09" ixz="1.89529937460801E-05" iyy="0.000159540694247497" iyz="-4.08015547511978E-08" izz="0.000103123225996245" />
    </inertial>
    <visual>
      <origin xyz="0 0 0" rpy="0 0 0" />
      <geometry>
        <mesh filename="package://mh2_description/meshes/link_ra5.STL" />
      </geometry>
      <material name="">
        <color rgba="1 1 1 1" />
      </material>
    </visual>
    <collision>
      <origin xyz="0 0 0" rpy="0 0 0" />
      <geometry>
        <mesh filename="package://mh2_description/meshes/link_ra5.STL" />
      </geometry>
    </collision>
  </link>
  <joint name="joint_ra5" type="revolute">
    <origin xyz="0 0 -0.14175" rpy="0 0 0" />
    <parent link="link_ra4" />
    <child link="link_ra5" />
    <axis xyz="0 0 1" />
    <limit lower="-2.79" upper="2.79" effort="0" velocity="0" />
  </joint>
  <link name="link_ra6">
    <inertial>
      <origin xyz="0.00108489437099928 -0.00393043101727358 -0.00051955823403671" rpy="0 0 0" />
      <mass value="0.0247999573093336" />
      <inertia ixx="1.52730200015668E-05" ixy="-1.54908198033713E-07" ixz="-1.38917661142737E-08" iyy="1.78050137602534E-05" iyz="7.72810096460296E-08" izz="1.61797951188175E-05" />
    </inertial>
    <visual>
      <origin xyz="0 0 0" rpy="0 0 0" />
      <geometry>
        <mesh filename="package://mh2_description/meshes/link_ra6.STL" />
      </geometry>
      <material name="">
        <color rgba="1 1 1 1" />
      </material>
    </visual>
    <collision>
      <origin xyz="0 0 0" rpy="0 0 0" />
      <geometry>
        <mesh filename="package://mh2_description/meshes/link_ra6.STL" />
      </geometry>
    </collision>
  </link>
  <joint name="joint_ra6" type="revolute">
    <origin xyz="-0.007347 0 -0.13425" rpy="0 0 0" />
    <parent link="link_ra5" />
    <child link="link_ra6" />
    <axis xyz="1 0 0" />
    <limit lower="-0.69" upper="0.69" effort="0" velocity="0" />
  </joint>
  <link name="link_ra7">
    <inertial>
      <origin xyz="1.88704721502952E-06 -0.0233772284650786 -0.0285390038214921" rpy="0 0 0" />
      <mass value="0.0325008367429399" />
      <inertia ixx="2.74872742818675E-05" ixy="1.54893722350726E-10" ixz="-3.98400557487223E-10" iyy="2.4126320731241E-05" iyz="7.53556999995862E-06" izz="2.05780383211257E-05" />
    </inertial>
    <visual>
      <origin xyz="0 0 0" rpy="0 0 0" />
      <geometry>
        <mesh filename="package://mh2_description/meshes/link_ra7.STL" />
      </geometry>
      <material name="">
        <color rgba="1 1 1 1" />
      </material>
    </visual>
    <collision>
      <origin xyz="0 0 0" rpy="0 0 0" />
      <geometry>
        <mesh filename="package://mh2_description/meshes/link_ra7.STL" />
      </geometry>
    </collision>
  </link>
  <joint name="joint_ra7" type="revolute">
    <origin xyz="0 0 0" rpy="0 0 0" />
    <parent link="link_ra6" />
    <child link="link_ra7" />
    <axis xyz="0 1 0" />
    <limit lower="-0.69" upper="0.69" effort="0" velocity="0" />
  </joint>
  <link name="link_tcp_r" />
  <joint name="joint_tcp_r" type="fixed">
    <origin xyz="0 0 0" rpy="0 0 0" />
    <parent link="link_ra7" />
    <child link="link_tcp_r" />
    <axis xyz="0 0 0" />
  </joint>

  <link name="link_rf0">
    <inertial>
      <origin xyz="2.5132E-05 0.0011436 -0.04987" rpy="0 0 0" />
      <mass value="0.029012" />
      <inertia ixx="3.2264E-06" ixy="1.745E-08" ixz="8.3711E-09" iyy="4.4944E-06" iyz="-3.854E-07" izz="2.1947E-06" />
    </inertial>
    <visual>
      <origin xyz="0 0 0" rpy="0 0 0" />
      <geometry>
        <mesh filename="package://mh2_description/meshes/link_rf0.STL" />
      </geometry>
      <material name="">
        <color rgba="1 1 1 1" />
      </material>
    </visual>
    <collision>
      <origin xyz="0 0 0" rpy="0 0 0" />
      <geometry>
        <mesh filename="package://mh2_description/meshes/link_rf0.STL" />
      </geometry>
    </collision>
  </link>
  <joint name="joint_rf0" type="revolute">
    <origin xyz="0 0.0117 -0.10388" rpy="0.01852 0 0" />
    <parent link="link_ra7" />
    <child link="link_rf0" />
    <axis xyz="1 0 0" />
    <limit lower="0" upper="0" effort="0" velocity="0" />
  </joint>
  <link name="link_rf1">
    <inertial>
      <origin xyz="-3.5034E-05 -0.0020662 -0.04984" rpy="0 0 0" />
      <mass value="0.029012" />
      <inertia ixx="3.2264E-06" ixy="1.8928E-08" ixz="-1.4265E-08" iyy="4.5076E-06" iyz="3.4297E-07" izz="2.1815E-06" />
    </inertial>
    <visual>
      <origin xyz="0 0 0" rpy="0 0 0" />
      <geometry>
        <mesh filename="package://mh2_description/meshes/link_rf1.STL" />
      </geometry>
      <material name="">
        <color rgba="1 1 1 1" />
      </material>
    </visual>
    <collision>
      <origin xyz="0 0 0" rpy="0 0 0" />
      <geometry>
        <mesh filename="package://mh2_description/meshes/link_rf1.STL" />
      </geometry>
    </collision>
  </link>
  <joint name="joint_rf1" type="revolute">
    <origin xyz="0 -0.0133 -0.10388" rpy="0 0 0" />
    <parent link="link_ra7" />
    <child link="link_rf1" />
    <axis xyz="1 0 0" />
    <limit lower="0" upper="0" effort="0" velocity="0" />
  </joint>

  <link name="link_head0">
    <inertial>
      <origin xyz="-5.88998710315813E-06 -0.000227858949464421 -0.0648726706664365" rpy="0 0 0" />
      <mass value="0.119507903391622" />
      <inertia ixx="0.000187779458297311" ixy="3.22501705449489E-08" ixz="5.17455948205894E-08" iyy="0.000187994301139424" iyz="1.5678143109891E-06" izz="5.19293347874966E-05" />
    </inertial>
    <visual>
      <origin xyz="0 0 0" rpy="0 0 0" />
      <geometry>
        <mesh filename="package://mh2_description/meshes/link_head0.STL" />
      </geometry>
      <material name="">
        <color rgba="0.792156862745098 0.819607843137255 0.933333333333333 1" />
      </material>
    </visual>
    <collision>
      <origin xyz="0 0 0" rpy="0 0 0" />
      <geometry>
        <mesh filename="package://mh2_description/meshes/link_head0.STL" />
      </geometry>
    </collision>
  </link>
  <joint name="joint_head0" type="revolute">
    <origin xyz="-0.00999 0 0.2305" rpy="0 0 0" />
    <parent link="body_link" />
    <child link="link_head0" />
    <axis xyz="0 0 1" />
    <limit lower="-1.57" upper="1.57" effort="0" velocity="0" />
  </joint>
  <link name="link_head1">
    <inertial>
      <origin xyz="0.0215491012889433 -0.00931547664406029 0.012169673381728" rpy="0 0 0" />
      <mass value="0.709736172689334" />
      <inertia ixx="0.00481427439184922" ixy="2.49363307958727E-05" ixz="0.000508800910945143" iyy="0.00400167834104791" iyz="2.24226588825156E-05" izz="0.00342565507539753" />
    </inertial>
    <visual>
      <origin xyz="0 0 0" rpy="0 0 0" />
      <geometry>
        <mesh filename="package://mh2_description/meshes/link_head1.STL" />
      </geometry>
      <material name="">
        <color rgba="0.792156862745098 0.819607843137255 0.933333333333333 1" />
      </material>
    </visual>
    <collision>
      <origin xyz="0 0 0" rpy="0 0 0" />
      <geometry>
        <mesh filename="package://mh2_description/meshes/link_head1.STL" />
      </geometry>
    </collision>
  </link>
  <joint name="joint_head1" type="revolute">
    <origin xyz="-0.0038159 0.0099079 0.04448" rpy="0 0 0" />
    <parent link="link_head0" />
    <child link="link_head1" />
    <axis xyz="-0.033355 0.99944 0" />
    <limit lower="-0.174" upper="0.348" effort="0" velocity="0" />
  </joint>
  <link name="link_camera0">
    <inertial>
      <origin xyz="-0.0009766 -0.0091004 0.01879" rpy="0 0 0" />
      <mass value="0.016173" />
      <inertia ixx="1.8585E-06" ixy="1.7157E-07" ixz="6.7302E-09" iyy="3.133E-06" iyz="-8.6581E-10" izz="3.7419E-06" />
    </inertial>
    <visual>
      <origin xyz="0 0 0" rpy="0 0 0" />
      <geometry>
        <mesh filename="package://mh2_description/meshes/link_camera0.STL" />
      </geometry>
      <material name="">
        <color rgba="0.79216 0.81961 0.93333 1" />
      </material>
    </visual>
    <collision>
      <origin xyz="0 0 0" rpy="0 0 0" />
      <geometry>
        <mesh filename="package://mh2_description/meshes/link_camera0.STL" />
      </geometry>
    </collision>
  </link>
  <joint name="joint_camera0" type="fixed">
    <origin xyz="0.10315 -0.0063628 -0.051136" rpy="2.6769 1.2842 2.6933" />
    <parent link="link_head1" />
    <child link="link_camera0" />
    <axis xyz="0 0 0" />
  </joint>
  <link name="link_camera1">
    <inertial>
      <origin xyz="-0.00028827 -0.0084742 -0.018117" rpy="0 0 0" />
      <mass value="0.021646" />
      <inertia ixx="1.2964E-05" ixy="-6.4406E-07" ixz="-2.1797E-08" iyy="2.0355E-06" iyz="-5.675E-08" izz="1.3467E-05" />
    </inertial>
    <visual>
      <origin xyz="0 0 0" rpy="0 0 0" />
      <geometry>
        <mesh filename="package://mh2_description/meshes/link_camera1.STL" />
      </geometry>
      <material name="">
        <color rgba="0.79216 0.81961 0.93333 1" />
      </material>
    </visual>
    <collision>
      <origin xyz="0 0 0" rpy="0 0 0" />
      <geometry>
        <mesh filename="package://mh2_description/meshes/link_camera1.STL" />
      </geometry>
    </collision>
  </link>
  <joint name="joint_camera1" type="fixed">
    <origin xyz="0.10454 -0.0063675 0.073133" rpy="3.0535 0.97467 3.0686" />
    <parent link="link_head1" />
    <child link="link_camera1" />
    <axis xyz="0 0 0" />
  </joint>



</robot>



